<?xml version="1.0" encoding="UTF-8"?>
<robot name="tsukutsuku" xmlns:xacro="http://ros.org/wiki/xacro">

  <xacro:property name="M_PI" value="3.1415926" />


  <material name="tsukurno_purple">
    <color rgba="${183/255} ${96/255} ${181/255} 0.66"/>
  </material>


  <!-- ===============  Body =============== -->
  <link name="base_link">
    <visual>
      <origin xyz="0 0 0" rpy="${M_PI/2} 0 ${-M_PI/2}" /> <!-- fix here  なぜかbase_linkの向きが変えられてる -->
      <geometry> 
        <mesh filename="package://tsukutsuku2_description/meshes/tsukutsuku/tsukutsuku_20210820.STL" scale="1 1 1" />
      </geometry>
      <material name="tsukurno_purple"/>
    </visual>
  </link>


  <link name="right_wheel_link">
      <origin xyz="0 0 0" rpy="0 0 0" />
  </link>

  <joint name="right_wheel_joint" type="continuous">
    <origin xyz="0.02225 -0.215 -0.01" rpy="${-M_PI/2} 0 0" />  <!-- fix here -->
    <parent link="base_link" />
    <child link="right_wheel_link" />
    <axis xyz="0 0 1" />
  </joint>


  <link name="left_wheel_link">
        <origin xyz="0 0 0" rpy="0 0 0" />
  </link>

  <joint name="left_wheel_joint" type="continuous">
    <origin xyz="0.02225 0.215 -0.01" rpy="${M_PI/2} 0 0" />  <!-- fix here -->
    <parent link="base_link" />
    <child link="left_wheel_link" />
    <axis xyz="0 0 1" />
  </joint>


  <!-- <link name="caster_link"></link>

  <joint name="caster_joint" type="fixed">
    <origin xyz="0.65 0 0.0" rpy="0 0 0" />
    <parent link="base_link" />
    <child link="caster_link" />
  </joint> -->


  <!--  ADD caster wheels !!!!!!!!!!!!!!!!!!!!! -->
  <!-- <link name="left_caster_wheel_link">
    <origin xyz="0 0 0" rpy="0 0 0" />
  </link>

  <joint name="left_caster_wheel_joint" type="continuous">
    <origin xyz="0.65 0.215 0.0" rpy="0 0 0" />  <============= fix here 
    <parent link="base_link" />
    <child link="left_caster_wheel_link" />
    <axis xyz="0 0 1" />
  </joint>

  <link name="right_caster_wheel_link">
    <origin xyz="0 0 0" rpy="0 0 0" />
  </link>

  <joint name="right_caster_wheel_joint" type="continuous">
    <origin xyz="0.65 -0.215 0.0" rpy="0 0 0" /> <============ fix here
    <parent link="base_link" />
    <child link="right_caster_wheel_link" />
    <axis xyz="0 0 1" />
  </joint> -->


  <link name="base_footprint" />

  <joint name="base_footprint_joint" type="fixed">
    <origin xyz="0 0 -0.05" rpy="0 0 0" />
    <parent link="base_link" />
    <child link="base_footprint" />
  </joint>


  <link name="velodyne">
    <origin xyz="0 0 0" rpy="0 0 0" />
  </link>

  <joint name="velodyne_joint" type="fixed">
    <origin xyz="0.27  0.00  0.827" rpy="0 0 0" />    <!-- fix here -->
    <parent link="base_link" />
    <child link="velodyne" />
    <axis xyz="0 0 0" />
  </joint>

  <!-- ??? -->
  <link name="hokuyo3d">
    <origin xyz="0 0 0" rpy="0 0 0" />
  </link>

  <joint name="hokuyo3d_joint" type="fixed">
    <origin xyz="0.465  0.00  0.85" rpy="0.00  0.02  -3.16" />
    <parent link="base_link" />
    <child link="hokuyo3d" />
    <axis xyz="0 0 0" />
  </joint>

<!-- 
  <link name="laser_front_left">
    <origin xyz="0 0 0" rpy="0 0 0" />
  </link>

  <joint name="laser_front_left_joint" type="fixed">
    <origin xyz="0.67  0.16  0.26" rpy="0.0  ${M_PI} ${M_PI + M_PI/4}" />
    <parent link="base_link" />
    <child link="laser_front_left" />
    <axis xyz="0 0 0" />
  </joint>


  <link name="laser_front_right">
    <origin xyz="0 0 0" rpy="0 0 0" />
  </link>

  <joint name="laser_front_right_joint" type="fixed">
    <origin xyz="0.67  -0.16  0.26" rpy="-0.0  ${M_PI} ${M_PI - M_PI/4}" />
    <parent link="base_link" />
    <child link="laser_front_right" />
    <axis xyz="0 0 0" />
  </joint>


  <link name="laser_rear">
    <origin xyz="0 0 0" rpy="0 0 0 0 0 0" />
  </link>

  <joint name="laser_rear_joint" type="fixed">
    <origin xyz="-0.12  0.00  0.20" rpy="3.14159  0.00  3.14159" />
    <parent link="base_link" />
    <child link="laser_rear" />
    <axis xyz="0 0 0" />
  </joint> -->

  <!-- livox -->
  <link name="livox_front_left">
    <origin xyz="0 0 0" rpy="0 0 0" />
  </link>

  <joint name="livox_front_left_joint" type="fixed">
    <origin xyz="0.67  0.16  0.26" rpy="0.0  ${M_PI} ${M_PI + M_PI/4}" /> <!-- fix here -->
    <parent link="base_link" />
    <child link="livox_front_left" />
    <axis xyz="0 0 0" />
  </joint>

  <link name="livox_front_right">
    <origin xyz="0 0 0" rpy="0 0 0" />
  </link>

  <joint name="livox_front_right_joint" type="fixed">
    <origin xyz="0.67  -0.16  0.26" rpy="-0.0  ${M_PI} ${M_PI - M_PI/4}" /> <!-- fix here -->
    <parent link="base_link" />
    <child link="livox_front_right" />
    <axis xyz="0 0 0" />
  </joint>

  <link name="livox_rear">
    <origin xyz="0 0 0" rpy="0 0 0 0 0 0" />
  </link>

  <joint name="livox_rear_joint" type="fixed">
    <origin xyz="-0.12  0.00  0.20" rpy="3.14159  0.00  3.14159" /> <!-- fix here -->
    <parent link="base_link" />
    <child link="livox_rear" />
    <axis xyz="0 0 0" />
  </joint>

  <link name="center_camera_link">
    <origin xyz="0 0 0" rpy="0 0 0" />
  </link>

  <joint name="center_camera_joint" type="fixed">
    <origin xyz="0.315  0.00  1.15" rpy="${-M_PI/2} 0 0" /> <!-- fix here -->
    <parent link="base_link" />
    <child link="center_camera_link" />
    <axis xyz="0 0 0" />
  </joint>

  <link name="center_camera">
    <origin xyz="0 0 0" rpy="0 0 0" />
  </link>

  <joint name="center_camera_link2center_camera_joint" type="fixed">
    <origin xyz="0.0  0.00  0.0" rpy="0 ${M_PI/2} 0" />  <!-- fix here??????? -->
    <parent link="center_camera_link" />
    <child link="center_camera" />
    <axis xyz="0 0 0" />
  </joint>

  <link name="imu_link">
    <origin xyz="0 0 0" rpy="0 0 0" />
  </link>

  <joint name="imu_joint" type="fixed">
    <origin xyz="0.376 0 0.745" rpy="${M_PI} 0 ${M_PI}" /> <!-- fix here -->
    <parent link="base_link" />
    <child link="imu_link" />
    <axis xyz="0 0 0" />
  </joint>

</robot>