<?xml version="1.0" encoding="UTF-8"?>
<robot name="tsukutsuku" xmlns:xacro="http://ros.org/wiki/xacro">

  <xacro:property name="M_PI" value="3.1415926" />


  <material name="tsukurno_purple">
    <color rgba="${183/255} ${96/255} ${181/255} 0.66"/>
  </material>


  <!-- ===============  Body =============== -->
  <link name="base_link">
    <visual>
      <origin xyz="0 0 0" rpy="${M_PI/2} 0 ${-M_PI/2}" /> <!-- fix here  なぜかbase_linkの向きが変えられてる -->
      <geometry> 
        <mesh filename="package://tsukutsuku2_description/meshes/tsukutsuku/tsukutsuku_20210820.STL" scale="1 1 1" />
      </geometry>
      <material name="tsukurno_purple"/>
    </visual>
  </link>


  <link name="rear_right_wheel_link">
      <origin xyz="0 0 0" rpy="0 0 0" />
  </link>

  <joint name="rear_right_wheel_joint" type="continuous">
    <origin xyz="0 -0.2985 0" rpy="${M_PI/2} 0 0" />  <!-- fix here -->
    <parent link="base_link" />
    <child link="rear_right_wheel_link" />
    <axis xyz="0 0 1" />
  </joint>


  <link name="rear_left_wheel_link">
        <origin xyz="0 0 0" rpy="0 0 0" />
  </link>

  <joint name="rear_left_wheel_joint" type="continuous">
    <origin xyz="0 0.2985 0" rpy="${M_PI/2} 0 0" />  <!-- fix here -->
    <parent link="base_link" />
    <child link="rear_left_wheel_link" />
    <axis xyz="0 0 1" />
  </joint>


  <!-- <link name="caster_link"></link>

  <joint name="caster_joint" type="fixed">
    <origin xyz="0.65 0 0.0" rpy="0 0 0" />
    <parent link="base_link" />
    <child link="caster_link" />
  </joint> -->


  <!--  ADD caster wheels !!!!!!!!!!!!!!!!!!!!! -->
  <link name="front_left_wheel_link">
    <origin xyz="0 0 0" rpy="0 0 0" />
  </link>

  <joint name="front_left_wheel_joint" type="continuous">
    <origin xyz="0.514 0.32 0.0225" rpy="${M_PI/2} 0 0" /> 
    <parent link="base_link" />
    <child link="front_left_wheel_link" />
    <axis xyz="0 0 1" />
  </joint>

  <link name="front_right_wheel_link">
    <origin xyz="0 0 0" rpy="0 0 0" />
  </link>

  <joint name="front_right_wheel_joint" type="continuous">
    <origin xyz="0.514 -0.32 0.0225" rpy="${M_PI/2} 0 0" /> 
    <parent link="base_link" />
    <child link="front_right_wheel_link" />
    <axis xyz="0 0 1" />
  </joint>


  <link name="base_footprint" />

  <joint name="base_footprint_joint" type="fixed">
    <origin xyz="0 0 -0.05" rpy="0 0 0" />
    <parent link="base_link" />
    <child link="base_footprint" />
  </joint>


  <link name="velodyne">
    <origin xyz="0 0 0" rpy="0 0 0" />
  </link>

  <joint name="velodyne_joint" type="fixed">
    <origin xyz="0.2813  0.00  0.9265" rpy="0 0 0" />    <!-- fix here -->
    <parent link="base_link" />
    <child link="velodyne" />
    <axis xyz="0 0 0" />
  </joint>

  <!-- livox (3台が1つのframeでpublishされてる 3台の配置はbase_linkから見たものになっているので tfは0,0,0) -->
  <link name="left_livox_link">
    <origin xyz="0 0 0" rpy="0 0 0" />
  </link>

  <joint name="left_livox_joint" type="fixed">
    <origin xyz="0.7151  0.3021  0.1425" rpy="${M_PI} 0 ${-M_PI/4}" />
    <parent link="base_link" />
    <child link="left_livox_link" />
    <axis xyz="0 0 0" />
  </joint>

  <link name="right_livox_link">
    <origin xyz="0 0 0" rpy="0 0 0" />
  </link>

  <joint name="right_livox_joint" type="fixed">
    <origin xyz="0.7151  -0.3021  0.1425" rpy="${M_PI} 0 ${M_PI/4}" />
    <parent link="base_link" />
    <child link="right_livox_link" />
    <axis xyz="0 0 0" />
  </joint>

  <!-- rearは後々yaw角回転の可能性あり -->
  <link name="rear_livox_link">
    <origin xyz="0 0 0" rpy="0 0 0" />
  </link>

  <joint name="rear_livox_joint" type="fixed">
    <origin xyz="-0.1425  0.00  0.1025" rpy="${M_PI} 0 0" /> 
    <parent link="base_link" />
    <child link="rear_livox_link" />
    <axis xyz="0 0 0" />
  </joint>

  <link name="center_camera_link">
    <origin xyz="0 0 0" rpy="0 0 0" />
  </link>

  <joint name="center_camera_joint" type="fixed">
    <origin xyz="0.1981  0.00  1.145" rpy="0 0 0" /> <!-- fix here -->
    <parent link="base_link" />
    <child link="center_camera_link" />
    <axis xyz="0 0 0" />
  </joint>


  <link name="imu_link">
    <origin xyz="0 0 0" rpy="0 0 0" />
  </link>

  <joint name="imu_joint" type="fixed">
    <origin xyz="0.5678 0 0.2374" rpy="${M_PI} 0 ${M_PI}" /> <!-- fix here -->
    <parent link="base_link" />
    <child link="imu_link" />
    <axis xyz="0 0 0" />
  </joint>

</robot>